<?xml version="1.0"?>
<sdf version="1.7">
  <model name='husky_turtlebot3_waffle'>
    <pose>-2 -0.5 0.01 0 -0 0</pose>
    <link name='base_footprint'>
      <self_collide>0</self_collide>
      <inertial>
        <pose>0 0 0 0 -0 0</pose>
        <inertia>
          <ixx>1</ixx>
          <ixy>0</ixy>
          <ixz>0</ixz>
          <iyy>1</iyy>
          <iyz>0</iyz>
          <izz>1</izz>
        </inertia>
        <mass>1</mass>
      </inertial>
      <enable_wind>0</enable_wind>
      <kinematic>0</kinematic>
    </link>
    <link name='base_link'>
      <inertial>
        <pose>-0.064 0 0.048 0 -0 0</pose>
        <inertia>
          <ixx>0.001</ixx>
          <ixy>0</ixy>
          <ixz>0</ixz>
          <iyy>0.001</iyy>
          <iyz>0</iyz>
          <izz>0.001</izz>
        </inertia>
        <mass>1</mass>
      </inertial>
      <collision name='base_collision'>
        <pose>-0.064 0 0.048 0 -0 0</pose>
        <geometry>
          <box>
            <size>0.265 0.265 0.089</size>
          </box>
        </geometry>
        <surface>
          <contact>
            <ode />
          </contact>
          <bounce />
          <friction>
            <torsional>
              <ode />
            </torsional>
            <ode />
          </friction>
        </surface>
        <max_contacts>10</max_contacts>
      </collision>
      <visual name='base_visual'>
        <pose>-0.064 0 0 0 -0 0</pose>
        <geometry>
          <mesh>
            <uri>model://husky_turtlebot3_waffle/meshes/waffle_base.dae</uri>
            <scale>0.001 0.001 0.001</scale>
          </mesh>
        </geometry>
      </visual>
      <self_collide>0</self_collide>
      <enable_wind>0</enable_wind>
      <kinematic>0</kinematic>
    </link>
    <link name='imu_link'>
      <sensor name='tb3_imu' type='imu'>
        <always_on>1</always_on>
        <update_rate>200</update_rate>
        <imu>
          <angular_velocity>
            <x>
              <noise type='gaussian'>
                <mean>0</mean>
                <stddev>0.0002</stddev>
              </noise>
            </x>
            <y>
              <noise type='gaussian'>
                <mean>0</mean>
                <stddev>0.0002</stddev>
              </noise>
            </y>
            <z>
              <noise type='gaussian'>
                <mean>0</mean>
                <stddev>0.0002</stddev>
              </noise>
            </z>
          </angular_velocity>
          <linear_acceleration>
            <x>
              <noise type='gaussian'>
                <mean>0</mean>
                <stddev>0.017</stddev>
              </noise>
            </x>
            <y>
              <noise type='gaussian'>
                <mean>0</mean>
                <stddev>0.017</stddev>
              </noise>
            </y>
            <z>
              <noise type='gaussian'>
                <mean>0</mean>
                <stddev>0.017</stddev>
              </noise>
            </z>
          </linear_acceleration>
        </imu>
        <plugin name='turtlebot3_imu' filename='libgazebo_ros_imu_sensor.so'>
          <initial_orientation_as_reference>false</initial_orientation_as_reference>
          <ros>
            <remapping>~/out:=imu</remapping>
          </ros>
        </plugin>

      </sensor>

      <sensor name="my_gps" type="gps">
          <always_on>true</always_on>
          <update_rate>30</update_rate>
          <plugin name="my_gps_plugin" filename="libgazebo_ros_gps_sensor.so">
            <ros>
              <namespace>/gps</namespace>
              <remapping>~/out:=data</remapping>
            </ros>
          </plugin>
      </sensor>

      <self_collide>0</self_collide>
      <inertial>
        <pose>0 0 0 0 -0 0</pose>
        <inertia>
          <ixx>1</ixx>
          <ixy>0</ixy>
          <ixz>0</ixz>
          <iyy>1</iyy>
          <iyz>0</iyz>
          <izz>1</izz>
        </inertia>
        <mass>1</mass>
      </inertial>
      <enable_wind>0</enable_wind>
      <kinematic>0</kinematic>
    </link>
    <link name='base_scan'>
      <inertial>
        <pose>-0.052 0 0.31 0 -0 0</pose>
        <inertia>
          <ixx>0.001</ixx>
          <ixy>0</ixy>
          <ixz>0</ixz>
          <iyy>0.001</iyy>
          <iyz>0</iyz>
          <izz>0.001</izz>
        </inertia>
        <mass>0.125</mass>
      </inertial>
      <collision name='lidar_sensor_collision'>
        <pose>-0.052 0 0.311 0 -0 0</pose>
        <geometry>
          <cylinder>
            <radius>0.0508</radius>
            <length>0.055</length>
          </cylinder>
        </geometry>
        <surface>
          <contact>
            <ode />
          </contact>
          <bounce />
          <friction>
            <torsional>
              <ode />
            </torsional>
            <ode />
          </friction>
        </surface>
        <max_contacts>10</max_contacts>
      </collision>
      <visual name='lidar_sensor_visual'>
        <pose>-0.064 0 0.321 0 -0 0</pose>
        <geometry>
          <mesh>
            <uri>model://husky_turtlebot3_waffle/meshes/lds.dae</uri>
            <scale>0.001 0.001 0.001</scale>
          </mesh>
        </geometry>
      </visual>
      <sensor name='hls_lfcd_lds' type='ray'>
        <always_on>1</always_on>
        <visualize>1</visualize>
        <pose>-0.064 0 0.321 0 -0 0</pose>
        <update_rate>5</update_rate>
        <ray>
          <scan>
            <horizontal>
              <samples>360</samples>
              <resolution>1</resolution>
              <min_angle>0</min_angle>
              <max_angle>6.28</max_angle>
            </horizontal>
            <vertical>
              <samples>1</samples>
              <min_angle>0</min_angle>
              <max_angle>0</max_angle>
            </vertical>
          </scan>
          <range>
            <min>0.32</min>
            <max>20.5</max>
            <resolution>0.015</resolution>
          </range>
          <noise>
            <type>gaussian</type>
            <mean>0</mean>
            <stddev>0.01</stddev>
          </noise>
        </ray>
        <plugin name='turtlebot3_laserscan' filename='libgazebo_ros_ray_sensor.so'>
          <ros>
            <remapping>~/out:=scan</remapping>
          </ros>
          <output_type>sensor_msgs/LaserScan</output_type>
          <frame_name>base_scan</frame_name>
        </plugin>
      </sensor>
      <self_collide>0</self_collide>
      <enable_wind>0</enable_wind>
      <kinematic>0</kinematic>
    </link>
    <link name='wheel_left_link'>
      <inertial>
        <pose>0 0.144 0.023 -1.57 0 0</pose>
        <inertia>
          <ixx>0.001</ixx>
          <ixy>0</ixy>
          <ixz>0</ixz>
          <iyy>0.001</iyy>
          <iyz>0</iyz>
          <izz>0.001</izz>
        </inertia>
        <mass>0.1</mass>
      </inertial>
      <collision name='wheel_left_collision'>
        <pose>0 0.144 0.023 -1.57 0 0</pose>
        <geometry>
          <cylinder>
            <radius>0.033</radius>
            <length>0.018</length>
          </cylinder>
        </geometry>
        <surface>
          <friction>
            <ode>
              <mu>100000</mu>
              <mu2>100000</mu2>
              <fdir1>0 0 0</fdir1>
              <slip1>0</slip1>
              <slip2>0</slip2>
            </ode>
            <torsional>
              <ode />
            </torsional>
          </friction>
          <contact>
            <ode>
              <soft_cfm>0</soft_cfm>
              <soft_erp>0.2</soft_erp>
              <kp>100000</kp>
              <kd>1</kd>
              <max_vel>0.01</max_vel>
              <min_depth>0.001</min_depth>
            </ode>
          </contact>
          <bounce />
        </surface>
        <max_contacts>10</max_contacts>
      </collision>
      <visual name='wheel_left_visual'>
        <pose>0 0.144 0.023 0 -0 0</pose>
        <geometry>
          <mesh>
            <uri>model://husky_turtlebot3_waffle/meshes/left_tire.dae</uri>
            <scale>0.001 0.001 0.001</scale>
          </mesh>
        </geometry>
      </visual>
      <self_collide>0</self_collide>
      <enable_wind>0</enable_wind>
      <kinematic>0</kinematic>
    </link>
    <link name='wheel_right_link'>
      <inertial>
        <pose>0 -0.144 0.023 -1.57 0 0</pose>
        <inertia>
          <ixx>0.001</ixx>
          <ixy>0</ixy>
          <ixz>0</ixz>
          <iyy>0.001</iyy>
          <iyz>0</iyz>
          <izz>0.001</izz>
        </inertia>
        <mass>0.1</mass>
      </inertial>
      <collision name='wheel_right_collision'>
        <pose>0 -0.144 0.023 -1.57 0 0</pose>
        <geometry>
          <cylinder>
            <radius>0.033</radius>
            <length>0.018</length>
          </cylinder>
        </geometry>
        <surface>
          <friction>
            <ode>
              <mu>100000</mu>
              <mu2>100000</mu2>
              <fdir1>0 0 0</fdir1>
              <slip1>0</slip1>
              <slip2>0</slip2>
            </ode>
            <torsional>
              <ode />
            </torsional>
          </friction>
          <contact>
            <ode>
              <soft_cfm>0</soft_cfm>
              <soft_erp>0.2</soft_erp>
              <kp>100000</kp>
              <kd>1</kd>
              <max_vel>0.01</max_vel>
              <min_depth>0.001</min_depth>
            </ode>
          </contact>
          <bounce />
        </surface>
        <max_contacts>10</max_contacts>
      </collision>
      <visual name='wheel_right_visual'>
        <pose>0 -0.144 0.023 0 -0 0</pose>
        <geometry>
          <mesh>
            <uri>model://husky_turtlebot3_waffle/meshes/right_tire.dae</uri>
            <scale>0.001 0.001 0.001</scale>
          </mesh>
        </geometry>
      </visual>
      <self_collide>0</self_collide>
      <enable_wind>0</enable_wind>
      <kinematic>0</kinematic>
    </link>
    <link name='caster_back_right_link'>
      <pose>-0.177 -0.064 -0.004 0 -0 0</pose>
      <inertial>
        <mass>0.001</mass>
        <inertia>
          <ixx>1e-05</ixx>
          <ixy>0</ixy>
          <ixz>0</ixz>
          <iyy>1e-05</iyy>
          <iyz>0</iyz>
          <izz>1e-05</izz>
        </inertia>
        <pose>0 0 0 0 -0 0</pose>
      </inertial>
      <collision name='collision'>
        <geometry>
          <sphere>
            <radius>0.005</radius>
          </sphere>
        </geometry>
        <surface>
          <contact>
            <ode>
              <soft_cfm>0</soft_cfm>
              <soft_erp>0.2</soft_erp>
              <kp>100000</kp>
              <kd>1</kd>
              <max_vel>0.01</max_vel>
              <min_depth>0.001</min_depth>
            </ode>
          </contact>
          <bounce />
          <friction>
            <torsional>
              <ode />
            </torsional>
            <ode />
          </friction>
        </surface>
        <max_contacts>10</max_contacts>
      </collision>
      <self_collide>0</self_collide>
      <enable_wind>0</enable_wind>
      <kinematic>0</kinematic>
    </link>
    <link name='caster_back_left_link'>
      <pose>-0.177 0.064 -0.004 0 -0 0</pose>
      <inertial>
        <mass>0.001</mass>
        <inertia>
          <ixx>1e-05</ixx>
          <ixy>0</ixy>
          <ixz>0</ixz>
          <iyy>1e-05</iyy>
          <iyz>0</iyz>
          <izz>1e-05</izz>
        </inertia>
        <pose>0 0 0 0 -0 0</pose>
      </inertial>
      <collision name='collision'>
        <geometry>
          <sphere>
            <radius>0.005</radius>
          </sphere>
        </geometry>
        <surface>
          <contact>
            <ode>
              <soft_cfm>0</soft_cfm>
              <soft_erp>0.2</soft_erp>
              <kp>100000</kp>
              <kd>1</kd>
              <max_vel>0.01</max_vel>
              <min_depth>0.001</min_depth>
            </ode>
          </contact>
          <bounce />
          <friction>
            <torsional>
              <ode />
            </torsional>
            <ode />
          </friction>
        </surface>
        <max_contacts>10</max_contacts>
      </collision>
      <self_collide>0</self_collide>
      <enable_wind>0</enable_wind>
      <kinematic>0</kinematic>
    </link>
    <link name='camera_link'>
      <inertial>
        <pose>0.069 -0.047 0.107 0 -0 0</pose>
        <inertia>
          <ixx>0.001</ixx>
          <ixy>0</ixy>
          <ixz>0</ixz>
          <iyy>0.001</iyy>
          <iyz>0</iyz>
          <izz>0.001</izz>
        </inertia>
        <mass>0.035</mass>
      </inertial>
      <collision name='collision'>
        <pose>0 0.047 -0.005 0 -0 0</pose>
        <geometry>
          <box>
            <size>0.008 0.13 0.022</size>
          </box>
        </geometry>
        <surface>
          <contact>
            <ode />
          </contact>
          <bounce />
          <friction>
            <torsional>
              <ode />
            </torsional>
            <ode />
          </friction>
        </surface>
        <max_contacts>10</max_contacts>
      </collision>
      <pose>0.069 -0.047 0.107 0 -0 0</pose>
      <sensor name='intel_realsense_r200_depth' type='depth'>
        <always_on>1</always_on>
        <update_rate>5</update_rate>
        <pose>0.064 -0.047 0.107 0 -0 0</pose>
        <camera name='realsense_depth_camera'>
          <horizontal_fov>1.047</horizontal_fov>
          <image>
            <width>320</width>
            <height>240</height>
          </image>
          <clip>
            <near>0.1</near>
            <far>100</far>
          </clip>
        </camera>
        <plugin name='intel_realsense_r200_depth_driver' filename='libgazebo_ros_camera.so'>
          <ros />
          <camera_name>intel_realsense_r200_depth</camera_name>
          <frame_name>camera_depth_frame</frame_name>
          <hack_baseline>0.07</hack_baseline>
          <min_depth>0.001</min_depth>
          <max_depth>5.0</max_depth>
        </plugin>
      </sensor>
      <collision name='collision'>
        <pose>0 0.047 -0.005 0 -0 0</pose>
        <geometry>
          <box>
            <size>0.008 0.13 0.022</size>
          </box>
        </geometry>
        <surface>
          <contact>
            <ode />
          </contact>
          <bounce />
          <friction>
            <torsional>
              <ode />
            </torsional>
            <ode />
          </friction>
        </surface>
        <max_contacts>10</max_contacts>
      </collision>
      <pose>0.069 -0.047 0.107 0 -0 0</pose>
      <self_collide>0</self_collide>
      <enable_wind>0</enable_wind>
      <kinematic>0</kinematic>
    </link>
    <joint name='base_joint' type='fixed'>
      <parent>base_footprint</parent>
      <child>base_link</child>
      <pose>0 0 0.01 0 -0 0</pose>
    </joint>
    <joint name='wheel_left_joint' type='revolute'>
      <parent>base_link</parent>
      <child>wheel_left_link</child>
      <pose>0 0.144 0.023 -1.57 0 0</pose>
      <axis>
        <xyz>0 0 1</xyz>
        <limit>
          <lower>-1e+16</lower>
          <upper>1e+16</upper>
        </limit>
        <dynamics>
          <spring_reference>0</spring_reference>
          <spring_stiffness>0</spring_stiffness>
        </dynamics>
      </axis>
    </joint>
    <joint name='wheel_right_joint' type='revolute'>
      <parent>base_link</parent>
      <child>wheel_right_link</child>
      <pose>0 -0.144 0.023 -1.57 0 0</pose>
      <axis>
        <xyz>0 0 1</xyz>
        <limit>
          <lower>-1e+16</lower>
          <upper>1e+16</upper>
        </limit>
        <dynamics>
          <spring_reference>0</spring_reference>
          <spring_stiffness>0</spring_stiffness>
        </dynamics>
      </axis>
    </joint>
    <joint name='caster_back_right_joint' type='ball'>
      <parent>base_link</parent>
      <child>caster_back_right_link</child>
    </joint>
    <joint name='caster_back_left_joint' type='ball'>
      <parent>base_link</parent>
      <child>caster_back_left_link</child>
    </joint>
    <joint name='lidar_joint' type='fixed'>
      <parent>base_link</parent>
      <child>base_scan</child>
      <pose>-0.064 0 1.21 0 -0 0</pose>
      <axis>
        <xyz>0 0 1</xyz>
        <limit>
          <lower>-1e+16</lower>
          <upper>1e+16</upper>
        </limit>
      </axis>
    </joint>
    <joint name='camera_joint' type='fixed'>
      <parent>base_link</parent>
      <child>camera_link</child>
      <pose>0.064 -0.065 0.094 0 -0 0</pose>
      <axis>
        <xyz>0 0 1</xyz>
        <limit>
          <lower>-1e+16</lower>
          <upper>1e+16</upper>
        </limit>
      </axis>
    </joint>
    <!-- <joint name='camera_rgb_joint' type='fixed'>
      <parent>camera_link</parent>
      <child>camera_rgb_frame</child>
      <pose>0.005 0.018 0.013 0 -0 0</pose>
      <axis>
        <xyz>0 0 1</xyz>
        <limit>
          <lower>-1e+16</lower>
          <upper>1e+16</upper>
        </limit>
      </axis>
    </joint> -->
    <plugin name='turtlebot3_diff_drive' filename='libgazebo_ros_diff_drive.so'>
      <ros />
      <update_rate>30</update_rate>
      <left_joint>wheel_left_joint</left_joint>
      <right_joint>wheel_right_joint</right_joint>
      <wheel_separation>0.287</wheel_separation>
      <wheel_diameter>0.066</wheel_diameter>
      <max_wheel_torque>20</max_wheel_torque>
      <max_wheel_acceleration>1.0</max_wheel_acceleration>
      <command_topic>cmd_vel</command_topic>
      <publish_odom>1</publish_odom>
      <publish_odom_tf>1</publish_odom_tf>
      <publish_wheel_tf>0</publish_wheel_tf>
      <odometry_topic>odom</odometry_topic>
      <odometry_frame>odom</odometry_frame>
      <robot_base_frame>base_footprint</robot_base_frame>
    </plugin>

    <plugin name='turtlebot3_joint_state' filename='libgazebo_ros_joint_state_publisher.so'>
      <ros>
        <remapping>~/out:=joint_states</remapping>
      </ros>
      <update_rate>30</update_rate>
      <joint_name>wheel_left_joint</joint_name>
      <joint_name>wheel_right_joint</joint_name>
    </plugin>

    <pose>-1.99992 -0.499987 0.008722 -1.1e-05 0.001564 0.007895</pose>
    <scale>1 1 1</scale>
    <link name='base_footprint'>
      <pose>-1.99992 -0.499987 0.008722 -1.1e-05 0.001564 0.007895</pose>
      <velocity>4.7e-05 -0.000497 -0.040079 -0.000146 0.001825 -0.000317</velocity>
      <acceleration>0.015015 -0.034383 -0.183632 0.142169 -0.234337 -0.004801</acceleration>
      <wrench>0.015015 -0.034383 -0.183632 0 -0 0</wrench>
    </link>
    <link name='base_link'>
      <pose>-1.99992 -0.499985 0.008722 -9e-06 0.001564 0.007898</pose>
      <velocity>0.000262 -0.000809 -0.039759 -0.001017 0.000608 -0.00065</velocity>
      <acceleration>0.140542 -0.126014 0.015921 -0.394499 -1.32727 0.002612</acceleration>
      <wrench>0.140542 -0.126014 0.015921 0 -0 0</wrench>
    </link>
    <link name='base_scan'>
      <pose>-1.99992 -0.499985 1.21722 -1.2e-05 0.001563 0.007901</pose>
      <velocity>0.000255 -0.000846 -0.039778 -0.000589 0.000798 -0.001039</velocity>
      <acceleration>0.054436 -0.100857 0.024621 -0.407769 -1.3636 -0.000906</acceleration>
      <wrench>0.006804 -0.012607 0.003078 0 -0 0</wrench>
    </link>
    <link name='camera_link'>
      <pose>-1.93039 -0.546436 0.115615 -1e-05 0.001563 0.0079</pose>
      <velocity>0.000288 -0.000877 -0.039826 -0.000845 0.000676 -0.000846</velocity>
      <acceleration>-0.088096 -0.058923 0.32354 -0.404016 -1.35469 0.001185</acceleration>
      <wrench>-0.003083 -0.002062 0.011324 0 -0 0</wrench>
    </link>
    <link name='caster_back_left_link'>
      <pose>-2.17743 -0.437385 0.004997 2.46667 0.40724 1.08802</pose>
      <velocity>0.000317 -0.000433 -0.0164 0.085597 0.062951 0</velocity>
      <acceleration>-0.002623 0.273187 22.8246 1.23316 -0.703068 0</acceleration>
      <wrench>-3e-06 0.000273 0.022825 0 -0 0</wrench>
    </link>
    <link name='caster_back_right_link'>
      <pose>-2.17642 -0.56538 0.004998 -2.29564 -0.288706 0.609177</pose>
      <velocity>0.000327 -0.00085 -0.038942 0.113268 0.05141 0</velocity>
      <acceleration>-0.046155 0.027458 0.077654 0 -0 0</acceleration>
      <wrench>-4.6e-05 2.7e-05 7.8e-05 0 -0 0</wrench>
    </link>
    <link name='imu_link'>
      <pose>-2 -0.5 -43974.7 0 -0 0</pose>
      <velocity>0 0 -928.383 0 -0 0</velocity>
      <acceleration>0 0 -9.8 0 -0 0</acceleration>
      <wrench>0 0 -9.8 0 -0 0</wrench>
    </link>
    <link name='wheel_left_link'>
      <pose>-1.99919 -0.499984 0.008735 -3.1e-05 -0.030628 0.007851</pose>
      <velocity>0.000311 -4.3e-05 -0.040244 0.004673 0.004285 0.001885</velocity>
      <acceleration>0.08455 -0.064388 0.149323 -1.19056 0.580198 3.12932</acceleration>
      <wrench>0.008455 -0.006439 0.014932 0 -0 0</wrench>
    </link>
    <link name='wheel_right_link'>
      <pose>-2.00077 -0.499996 0.008737 -2.7e-05 0.038141 0.007913</pose>
      <velocity>-0.000133 -5.2e-05 -0.039656 0.004945 0.004781 0.001244</velocity>
      <acceleration>0.079134 -0.076051 -0.43328 -0.837183 0.744163 3.13292</acceleration>
      <wrench>0.007913 -0.007605 -0.043328 0 -0 0</wrench>
    </link>

    <include>
      <uri>model://led_array</uri>
      <pose>-0.02 0 0 -1.17075 0 1.57075</pose>
    </include>

    <joint name="led_array_joint" type="fixed">
      <parent>base_link</parent>
      <child>led_array::led_array_base</child>
    </joint>

  </model>
</sdf>
