<?xml version="1.0" ?>
<!-- =================================================================================== -->
<!-- |    This document was autogenerated by xacro from mp_500.urdf.xacro              | -->
<!-- |    EDITING THIS FILE BY HAND IS NOT RECOMMENDED                                 | -->
<!-- =================================================================================== -->
<robot name="mp_500">
<gazebo>

<!-- Use gazebo_ros_joint_state_publisher instead of publishWheelJointState -->
      <plugin name="joint_states" filename="libgazebo_ros_joint_state_publisher.so">
        <joint_name>wheel_left_joint</joint_name>
        <joint_name>wheel_right_joint</joint_name>
      </plugin>


      <plugin name='diff_drive' filename='libgazebo_ros_diff_drive.so'>
        <ros>
          <!-- Set namespace -->
          <!-- <namespace></namespace> -->
        </ros>

        <!-- Replace camelCase elements with camel_case ones -->
        <update_rate>100</update_rate>
        <left_joint>wheel_left_joint</left_joint>
        <right_joint>wheel_right_joint</right_joint>
        <wheel_separation>0.592</wheel_separation>
        <wheel_diameter>0.260</wheel_diameter>
        <publish_odom>true</publish_odom>
        <publish_odom_tf>true</publish_odom_tf>
        <publish_wheel_tf>true</publish_wheel_tf>
        <command_topic>cmd_vel</command_topic>

        <odometry_topic>odom</odometry_topic>
        <odometry_frame>odom</odometry_frame>
        <robot_base_frame>base_footprint</robot_base_frame>

        <!-- wheelTorque and wheelAcceleration now have max_ prefix -->
        <max_wheel_torque>200</max_wheel_torque>
        <max_acceleration>1.0</max_acceleration>



      </plugin>
</gazebo>

<gazebo reference="lidar_1_link">
    <sensor name="lidar_1_sensor" type="ray">
      <always_on>true</always_on>
      <pose>0 0 0 0 0 0</pose>
      <visualize>true</visualize>
      <update_rate>100</update_rate>
      <ray>
        <scan>
          <horizontal>
            <samples>720</samples>
            <resolution>1</resolution>
            <min_angle>-1.48</min_angle>
            <max_angle>1.48</max_angle>
          </horizontal>
        </scan>
        <range>
          <min>0.10</min>
          <max>30.0</max>
          <resolution>0.05</resolution>
        </range>
        <noise>
          <type>gaussian</type>
          <!-- Noise parameters based on published spec for Hokuyo laser
                   achieving "+-30mm" accuracy at range < 10m.  A mean of 0.0m and
                   stddev of 0.01m will put 99.7% of samples within 0.03m of the true
                   reading. -->
          <mean>0.0</mean>
          <stddev>0.01</stddev>
        </noise>
      </ray>
      <plugin filename="libgazebo_ros_ray_sensor.so" name="lidar_1">
      <ros>
        <!-- <namespace>   </namespace> -->
        <argument>~/out:=scan</argument>
      </ros>
      <!-- Set output to sensor_msgs/LaserScan to get same output type as gazebo_ros_laser -->
      <output_type>sensor_msgs/LaserScan</output_type>
      <frame_name>lidar_1_link</frame_name>
      </plugin>
    </sensor>
  </gazebo>

  <link name="base_footprint"/>
  <joint name="base_footprint_joint" type="fixed">
    <origin rpy="0 0 0" xyz="0 0 0"/>
    <axis xyz="0 0 -1"/>
    <!-- <limit effort="1000.0" lower="-1e+16" upper="1e+16" velocity="3.5"/> -->
    <joint_properties damping="1" friction="1"/>
    <parent link="base_footprint"/>
    <child link="base_link"/>
  </joint>
  <link name="base_link">
    <inertial>
      <mass value="5"/>
      <origin rpy="0 0 0" xyz="0 0 0"/>
      <inertia ixx="1.71402" ixy="0.0" ixz="0.0" iyy="0.8856" iyz="0.0" izz="2.5725"/>
    </inertial>
    <visual name="body">
      <origin rpy="0 0 1.570796" xyz="0.0 0.0 0"/>
      <geometry>
        <mesh filename="package://neo_simulation2/robots/mp_500/meshes/MP-500-BODY.dae" scale="0.001 0.001 0.001"/>
      </geometry>
    </visual>
    <collision name="body_collision">
      <origin rpy=" 0 0. 1.570796" xyz="0.0 0.0 0.0"/>
      <geometry>
        <mesh filename="package://neo_simulation2/robots/mp_500/meshes/MP-500-BODY.dae" scale="0.001 0.001 0.001"/>
      </geometry>
    </collision>
  </link>
  <joint name="caster_wheel_joint" type="fixed">
    <origin rpy="-1.570796 0 1.570796 " xyz="-0.43 0. 0.176"/>
    <axis xyz="0 -1 0"/>
    <limit effort="1000.0" lower="-1e+16" upper="1e+16" velocity="3.5"/>
    <parent link="base_link"/>
    <child link="caster_wheel_link"/>
    <joint_properties damping="1.0" friction="1.0"/>
  </joint>
  <link name="caster_wheel_link" type="wheel">
    <inertial>
      <mass value="1.82362"/>
      <inertia ixx="0.00499743171" ixy="0.00000004464" ixz="-0.00000002245" iyy="0.00499741733" iyz="0.00000000164" izz="0.00839239692"/>
    </inertial>
    <visual name="castor_wheel">
      <origin rpy="0 0 0" xyz="0 0 0"/>
      <geometry>
        <mesh filename="package://neo_simulation2/robots/mp_500/meshes/MP-500-WHEEL.dae" scale="0.001 0.001 0.001"/>
      </geometry>
    </visual>
    <collision>
      <origin rpy="0 0 0" xyz="0 0 0"/>
      <geometry>
        <mesh filename="package://neo_simulation2/robots/mp_500/meshes/MP-500-WHEEL.dae" scale="0.001 0.001 0.001"/>
      </geometry>
    </collision>
  </link>
  <gazebo reference="caster_wheel_link">
    <kp>8000.0</kp>
    <kd>1460.0</kd>
    <mu1>0.5</mu1>
    <mu2>0.2</mu2>
    <fdir1>1 0 0</fdir1>
    <maxVel>3.0</maxVel>
    <minDepth>0.00</minDepth>
  </gazebo>
  <joint name="wheel_right_joint" type="revolute">
    <origin rpy="0 0 -1.570796" xyz="0. -0.25 0.13"/>
    <limit effort="1000.0" lower="-1e+16" upper="1e+16" velocity="3.5"/>
    <axis xyz="-1 0 0"/>
    <joint_properties damping="0" friction="0.0"/>
    <parent link="base_link"/>
    <child link="wheel_right_link"/>
  </joint>
  <link name="wheel_right_link" type="wheel">
    <inertial>
      <origin rpy="0 0 0" xyz="0 0 0"/>
      <mass value="1.82362"/>
      <inertia ixx="0.00399743171" ixy="0.00000004464" ixz="-0.00000002245" iyy="0.00399741733" iyz="-0.00000000164" izz="0.00739239692"/>
    </inertial>
    <visual>
      <origin rpy="0 0 0" xyz="0 0 0"/>
      <geometry>
        <mesh filename="package://neo_simulation2/robots/mp_500/meshes/MP-500-WHEEL-RIGHT.dae" scale="0.001 0.001 0.001"/>
      </geometry>
    </visual>
    <collision>
      <origin rpy="0 0 0" xyz="0 0 0"/>
      <geometry>
        <mesh filename="package://neo_simulation2/robots/mp_500/meshes/MP-500-WHEEL-RIGHT.dae" scale="0.001 0.001 0.001"/>
      </geometry>
    </collision>
  </link>
  <joint name="wheel_left_joint" type="revolute">
    <origin rpy="0 0 -1.570796" xyz="0. 0.25 0.13"/>
    <limit effort="1000.0" lower="-1e+16" upper="1e+16" velocity="3.5"/>
    <axis xyz="-1 0 0"/>
    <joint_properties damping="0" friction="0.0"/>
    <parent link="base_link"/>
    <child link="wheel_left_link"/>
  </joint>
  <link name="wheel_left_link" type="wheel">
    <inertial>
      <origin rpy="0 0 0" xyz="0 0 0"/>
      <mass value="1.82362"/>
      <inertia ixx="0.00399743171" ixy="0.00000004464" ixz="-0.00000002245" iyy="0.00399741733" iyz="-0.00000000164" izz="0.00739239692"/>
    </inertial>
    <visual>
      <origin rpy="0 0 3.14" xyz="0 0 0"/>
      <geometry>
        <mesh filename="package://neo_simulation2/robots/mp_500/meshes/MP-500-WHEEL-LEFT.dae" scale="0.001 0.001 0.001"/>
      </geometry>
    </visual>
    <collision>
      <origin rpy="0 0 0" xyz="0 0 0"/>
      <geometry>
        <mesh filename="package://neo_simulation2/robots/mp_500/meshes/MP-500-WHEEL-LEFT.dae" scale="0.001 0.001 0.001"/>
      </geometry>
    </collision>
  </link>
  <joint name="lidar_1_joint" type="fixed">
    <axis xyz="0 1 0"/>
    <origin rpy="3.14 0 0" xyz="0.244 0 0.141"/>
    <parent link="base_link"/>
    <child link="lidar_1_link"/>
  </joint>
  <link name="lidar_1_link" type="laser">
    <inertial>
      <mass value="0.001"/>
      <origin rpy="0 0 0" xyz="0 0 0"/>
      <inertia ixx="0.0001" ixy="0" ixz="0" iyy="0.000001" iyz="0" izz="0.0001"/>
    </inertial>
    <visual>
      <origin rpy="-1.57 0 3.14" xyz="0 0 -0.12"/>
      <geometry>
        <mesh filename="package://neo_simulation2/components/sensors/SICK-S300.dae" scale="0.001 0.001 0.001"/>
      </geometry>
    </visual>
    <collision>
      <origin rpy="-1.57 0 3.14" xyz="0 0 -0.12"/>
      <geometry>
        <mesh filename="package://neo_simulation2/components/sensors/SICK-S300.dae" scale="0.001 0.001 0.001"/>
      </geometry>
    </collision>
  </link>
  <!--+++++++++++++++++++ IMU ++++++++++++++++++++++++-->
  <!-- Comment or uncomment based on your requirement -->
  <!--><xacro:imu name="imu" parent="base_footprint">
    <origin xyz="0.100 0 0.300" rpy="0 0 3.14" />
  </xacro:imu><-->
  <!--+++++++++++++++++++ Ultra Sonic ++++++++++++++++++++++++-->
  <!-- Comment or uncomment based on your requirement -->
  <!-- SENSOR 1 -->
  <!--><xacro:us_sensor name="us_1" parent="base_footprint">
    <origin xyz="0.100 0 0.500" rpy="0 3.14 3.14" />
  </xacro:us_sensor><-->
  <!-- SENSOR 2 -->
  <!-- xacro:us_sensor name="us_2" parent="base_footprint">
    <origin xyz="0.110 0 0.300" rpy="0 3.14 3.14" />
  </xacro:us_sensor-->
  <!-- SENSOR 3 -->
  <!-- xacro:us_sensor name="us_3" parent="base_footprint">
    <origin xyz="0.120 0 0.300" rpy="0 3.14 3.14" />
  </xacro:us_sensor-->
  <!-- SENSOR 4 -->
  <!-- xacro:us_sensor name="us_4" parent="base_footprint">
    <origin xyz="0.130 0 0.300" rpy="0 3.14 3.14" />
  </xacro:us_sensor-->
  <!-- SENSOR 5 -->
  <!-- xacro:us_sensor name="us_5" parent="base_footprint">
    <origin xyz="0.140 0 0.300" rpy="0 3.14 3.14" />
  </xacro:us_sensor-->
  <!-- SENSOR 6 -->
  <!-- xacro:us_sensor name="us_6" parent="base_footprint">
    <origin xyz="0.150 0 0.300" rpy="0 3.14 3.14" />
  </xacro:us_sensor-->
  <!-- SENSOR 7 -->
  <!-- xacro:us_sensor name="us_7" parent="base_footprint">
    <origin xyz="0.160 0 0.300" rpy="0 3.14 3.14" />
  </xacro:us_sensor-->
  <!-- SENSOR 8 -->
  <!-- xacro:us_sensor name="us_8" parent="base_footprint">
    <origin xyz="0.170 0 0.300" rpy="0 3.14 3.14" />
  </xacro:us_sensor-->
  <!-- SENSOR 9 -->
  <!-- xacro:us_sensor name="us_9" parent="base_footprint">
    <origin xyz="0.180 0 0.300" rpy="0 3.14 3.14" />
  </xacro:us_sensor-->
  <!-- SENSOR 10 -->
  <!-- xacro:us_sensor name="us_10" parent="base_footprint">
    <origin xyz="0.100 0 0.300" rpy="0 3.14 3.14" />
  </xacro:us_sensor-->
  <!-- SENSOR 11 -->
  <!-- xacro:us_sensor name="us_11" parent="base_footprint">
    <origin xyz="0.100 0 0.300" rpy="0 3.14 3.14" />
  </xacro:us_sensor-->
  <!-- SENSOR 12 -->
  <!-- xacro:us_sensor name="us_12" parent="base_footprint">
    <origin xyz="0.190 0 0.300" rpy="0 3.14 3.14" />
  </xacro:us_sensor-->
  <!-- SENSOR 13 -->
  <!-- xacro:us_sensor name="us_13" parent="base_footprint">
    <origin xyz="0.200 0 0.300" rpy="0 3.14 3.14" />
  </xacro:us_sensor-->
  <!-- SENSOR 14 -->
  <!-- xacro:us_sensor name="us_14" parent="base_footprint">
    <origin xyz="0.210 0 0.300" rpy="0 3.14 3.14" />
  </xacro:us_sensor-->
  <!-- SENSOR 15 -->
  <!-- xacro:us_sensor name="us_15" parent="base_footprint">
    <origin xyz="0.220 0 0.300" rpy="0 3.14 3.14" />
  </xacro:us_sensor-->
  <!-- SENSOR 16 -->
  <!-- xacro:us_sensor name="us_16" parent="base_footprint">
    <origin xyz="0.230 0 0.300" rpy="0 3.14 3.14" />
  </xacro:us_sensor-->
  <!--Camera  -->
  <!-- <xacro:camera name="camera" parent="base_footprint">
    <origin xyz="0 0 0.38" rpy="0 0 0" />
  </xacro:camera>
 -->
</robot>
